<?xml version="1.0"?>
<robot xmlns:xacro="http://www.ros.org/wiki/xacro">

    <xacro:include filename="colours.xacro" />
    <xacro:include filename="inertial_macros.xacro" />
    
    <!-- BASE LINK -->
    <link name="base_link"> 
    </link>

    <!-- CHASSIS -->
    <joint name = "chassis_joint" type= "fixed"> 
        <parent link = "base_link"/>
        <child link = "chassis_link"/>
        <origin xyz = "0 0 0"/>
    </joint>

    <link name = "chassis_link">
        <visual>
            <origin xyz = "0 0 0.15"/>
            <geometry>
                <box size = "1 0.7 0.3"/>
            </geometry>
            <material name ="red"/>
        </visual>
        <collision>
            <origin xyz = "0 0 0.15"/>
            <geometry>
                <box size = "1 0.7 0.3"/>
            </geometry>
        </collision>
        <xacro:inertial_box mass="1" x="1" y="0.7" z="0.3">
            <origin xyz="0 0 0.15" rpy="0 0 0"/>
        </xacro:inertial_box>
    </link>

    <gazebo reference = "chassis_link">
        <material> Gazebo/Red </material>
    </gazebo>


    <!-- LEFT FRONT WHEEL-->
    <joint name = "lf_wheel_joint" type= "continuous">
        <parent link = "chassis_link"/>
        <child link = "lf_wheel_link"/>
        <origin xyz = "0.3 0.4 0" rpy="-${pi/2} 0 0"/>
        <axis xyz = "0 0 1"/>
    </joint>

    <link name = "lf_wheel_link">
        <visual>
            <geometry>
                <cylinder radius = "0.15" length="0.1"/>
            </geometry>
            <material name ="white"/>
        </visual>
        <collision>
            <geometry>
                <cylinder radius = "0.15" length="0.1"/>
            </geometry>
        </collision>
        <xacro:inertial_cylinder mass="0.1" length="0.1" radius="0.15">
            <origin xyz="0 0 0" rpy="0 0 0"/>
        </xacro:inertial_cylinder>
    </link>

    <gazebo reference = "lf_wheel_link">
        <material> Gazebo/White </material>
    </gazebo>


    <!-- RIGHT FRONT WHEEL-->
    <joint name = "rf_wheel_joint" type= "continuous">
        <parent link = "chassis_link"/>
        <child link = "rf_wheel_link"/>
        <origin xyz = "0.3 -0.4 0" rpy="${pi/2} 0 0"/>
        <axis xyz = "0 0 -1"/>
    </joint>

    <link name = "rf_wheel_link">
        <visual>
            <geometry>
                <cylinder radius = "0.15" length="0.1"/>
            </geometry>
            <material name ="white"/>
        </visual>
        <collision>
            <geometry>
                <cylinder radius = "0.15" length="0.1"/>
            </geometry>
        </collision>
        <xacro:inertial_cylinder mass="0.1" length="0.1" radius="0.15">
            <origin xyz="0 0 0" rpy="0 0 0"/>
        </xacro:inertial_cylinder>
    </link>

    <gazebo reference = "rf_wheel_link">
        <material> Gazebo/White </material>
    </gazebo>


    <!-- LEFT BACK WHEEL-->
    <joint name = "lb_wheel_joint" type= "continuous">
        <parent link = "chassis_link"/>
        <child link = "lb_wheel_link"/>
        <origin xyz = "-0.3 0.4 0" rpy="-${pi/2} 0 0"/>
        <axis xyz = "0 0 1"/>
    </joint>

    <link name = "lb_wheel_link">
        <visual>
            <geometry>
                <cylinder radius = "0.15" length="0.1"/>
            </geometry>
            <material name ="white"/>
        </visual>
        <collision>
            <geometry>
                <cylinder radius = "0.15" length="0.1"/>
            </geometry>
        </collision>
        <xacro:inertial_cylinder mass="0.1" length="0.1" radius="0.15">
            <origin xyz="0 0 0" rpy="0 0 0"/>
        </xacro:inertial_cylinder>
    </link>

    <gazebo reference = "lb_wheel_link">
        <material> Gazebo/White </material>
    </gazebo>


    <!-- RIGHT BACK WHEEL-->
    <joint name = "rb_wheel_joint" type= "continuous">
        <parent link = "chassis_link"/>
        <child link = "rb_wheel_link"/>
        <origin xyz = "-0.3 -0.4 0" rpy="${pi/2} 0 0"/>
        <axis xyz = "0 0 -1"/>
    </joint>

    <link name = "rb_wheel_link">
        <visual>
            <geometry>
                <cylinder radius = "0.15" length="0.1"/>
            </geometry>
            <material name ="white"/>
        </visual>
        <collision>
            <geometry>
                <cylinder radius = "0.15" length="0.1"/>
            </geometry>
        </collision>
        <xacro:inertial_cylinder mass="0.1" length="0.1" radius="0.15">
            <origin xyz="0 0 0" rpy="0 0 0"/>
        </xacro:inertial_cylinder>
    </link>

    <gazebo reference = "rb_wheel_link">
        <material> Gazebo/White </material>
    </gazebo>

</robot>